2022-11-21 00:15:02,922 INFO    MainThread:1590552 [internal.py:wandb_internal():90] W&B internal server running at pid: 1590552, started at: 2022-11-21 00:15:02.918829
2022-11-21 00:15:02,925 INFO    WriterThread:1590552 [datastore.py:open_for_write():75] open: /fsx/ganayu/code/SuperShaper/wandb/offline-run-20221121_001459-2bfo1c67/run-2bfo1c67.wandb
2022-11-21 00:15:02,925 DEBUG   HandlerThread:1590552 [handler.py:handle_request():141] handle_request: run_start
2022-11-21 00:15:02,955 DEBUG   HandlerThread:1590552 [meta.py:__init__():35] meta init
2022-11-21 00:15:02,955 DEBUG   HandlerThread:1590552 [meta.py:__init__():49] meta init done
2022-11-21 00:15:02,955 DEBUG   HandlerThread:1590552 [meta.py:probe():209] probe
2022-11-21 00:15:02,974 DEBUG   HandlerThread:1590552 [meta.py:_setup_git():199] setup git
2022-11-21 00:15:03,066 DEBUG   HandlerThread:1590552 [meta.py:_setup_git():206] setup git done
2022-11-21 00:15:03,066 DEBUG   HandlerThread:1590552 [meta.py:_save_pip():53] save pip
2022-11-21 00:15:03,071 DEBUG   HandlerThread:1590552 [meta.py:_save_pip():67] save pip done
2022-11-21 00:15:03,073 DEBUG   HandlerThread:1590552 [meta.py:_save_conda():74] save conda
2022-11-21 00:15:03,926 WARNING MainThread:1590552 [internal.py:is_dead():387] Internal process exiting, parent pid 1590513 disappeared
2022-11-21 00:15:03,926 ERROR   MainThread:1590552 [internal.py:wandb_internal():149] Internal process shutdown.
2022-11-21 00:15:03,927 INFO    WriterThread:1590552 [datastore.py:close():279] close: /fsx/ganayu/code/SuperShaper/wandb/offline-run-20221121_001459-2bfo1c67/run-2bfo1c67.wandb
2022-11-21 00:15:03,932 INFO    SenderThread:1590552 [sender.py:finish():1111] shutting down sender
2022-11-21 00:15:17,111 DEBUG   HandlerThread:1590552 [meta.py:_save_conda():84] save conda done
2022-11-21 00:15:17,111 DEBUG   HandlerThread:1590552 [meta.py:probe():247] probe done
2022-11-21 00:15:17,878 INFO    HandlerThread:1590552 [handler.py:finish():806] shutting down handler
2022-11-21 00:15:17,878 INFO    MainThread:1590552 [internal.py:handle_exit():80] Internal process exited
