2022-08-17 02:23:55,565 INFO    MainThread:1534727 [internal.py:wandb_internal():90] W&B internal server running at pid: 1534727, started at: 2022-08-17 02:23:55.562809
2022-08-17 02:23:55,596 INFO    WriterThread:1534727 [datastore.py:open_for_write():75] open: /fsx/ganayu/code/SuperShaper/wandb/offline-run-20220817_022353-219ojdkh/run-219ojdkh.wandb
2022-08-17 02:23:55,596 DEBUG   HandlerThread:1534727 [handler.py:handle_request():141] handle_request: run_start
2022-08-17 02:23:55,622 DEBUG   HandlerThread:1534727 [meta.py:__init__():35] meta init
2022-08-17 02:23:55,622 DEBUG   HandlerThread:1534727 [meta.py:__init__():49] meta init done
2022-08-17 02:23:55,622 DEBUG   HandlerThread:1534727 [meta.py:probe():209] probe
2022-08-17 02:23:55,642 DEBUG   HandlerThread:1534727 [meta.py:_setup_git():199] setup git
2022-08-17 02:23:55,758 DEBUG   HandlerThread:1534727 [meta.py:_setup_git():206] setup git done
2022-08-17 02:23:55,759 DEBUG   HandlerThread:1534727 [meta.py:_save_pip():53] save pip
2022-08-17 02:23:55,769 DEBUG   HandlerThread:1534727 [meta.py:_save_pip():67] save pip done
2022-08-17 02:23:55,770 DEBUG   HandlerThread:1534727 [meta.py:_save_conda():74] save conda
2022-08-17 02:24:04,599 WARNING MainThread:1534727 [internal.py:is_dead():387] Internal process exiting, parent pid 1534694 disappeared
2022-08-17 02:24:04,599 ERROR   MainThread:1534727 [internal.py:wandb_internal():149] Internal process shutdown.
2022-08-17 02:24:04,599 INFO    WriterThread:1534727 [datastore.py:close():279] close: /fsx/ganayu/code/SuperShaper/wandb/offline-run-20220817_022353-219ojdkh/run-219ojdkh.wandb
2022-08-17 02:24:04,824 DEBUG   HandlerThread:1534727 [meta.py:_save_conda():84] save conda done
2022-08-17 02:24:04,825 DEBUG   HandlerThread:1534727 [meta.py:probe():247] probe done
2022-08-17 02:24:05,461 INFO    HandlerThread:1534727 [handler.py:finish():806] shutting down handler
2022-08-17 02:24:05,594 INFO    SenderThread:1534727 [sender.py:finish():1111] shutting down sender
2022-08-17 02:24:05,595 INFO    MainThread:1534727 [internal.py:handle_exit():80] Internal process exited
