2022-12-24 07:00:22,964 INFO    MainThread:2132148 [internal.py:wandb_internal():90] W&B internal server running at pid: 2132148, started at: 2022-12-24 07:00:22.961918
2022-12-24 07:00:23,000 INFO    WriterThread:2132148 [datastore.py:open_for_write():75] open: /fsx/ganayu/code/SuperShaper/wandb/offline-run-20221224_070021-3p0i42iz/run-3p0i42iz.wandb
2022-12-24 07:00:23,001 DEBUG   HandlerThread:2132148 [handler.py:handle_request():141] handle_request: run_start
2022-12-24 07:00:23,024 DEBUG   HandlerThread:2132148 [meta.py:__init__():35] meta init
2022-12-24 07:00:23,024 DEBUG   HandlerThread:2132148 [meta.py:__init__():49] meta init done
2022-12-24 07:00:23,024 DEBUG   HandlerThread:2132148 [meta.py:probe():209] probe
2022-12-24 07:00:23,045 DEBUG   HandlerThread:2132148 [meta.py:_setup_git():199] setup git
2022-12-24 07:00:23,170 DEBUG   HandlerThread:2132148 [meta.py:_setup_git():206] setup git done
2022-12-24 07:00:23,170 DEBUG   HandlerThread:2132148 [meta.py:_save_pip():53] save pip
2022-12-24 07:00:23,176 DEBUG   HandlerThread:2132148 [meta.py:_save_pip():67] save pip done
2022-12-24 07:00:23,176 DEBUG   HandlerThread:2132148 [meta.py:_save_conda():74] save conda
2022-12-24 07:00:32,020 WARNING MainThread:2132148 [internal.py:is_dead():387] Internal process exiting, parent pid 2131775 disappeared
2022-12-24 07:00:32,021 ERROR   MainThread:2132148 [internal.py:wandb_internal():149] Internal process shutdown.
2022-12-24 07:00:32,021 INFO    WriterThread:2132148 [datastore.py:close():279] close: /fsx/ganayu/code/SuperShaper/wandb/offline-run-20221224_070021-3p0i42iz/run-3p0i42iz.wandb
2022-12-24 07:00:32,717 DEBUG   HandlerThread:2132148 [meta.py:_save_conda():84] save conda done
2022-12-24 07:00:32,717 DEBUG   HandlerThread:2132148 [meta.py:probe():247] probe done
2022-12-24 07:00:32,989 INFO    SenderThread:2132148 [sender.py:finish():1111] shutting down sender
2022-12-24 07:00:33,222 INFO    HandlerThread:2132148 [handler.py:finish():806] shutting down handler
2022-12-24 07:00:33,223 INFO    MainThread:2132148 [internal.py:handle_exit():80] Internal process exited
