2022-12-21 18:54:33,178 INFO    MainThread:2188033 [internal.py:wandb_internal():90] W&B internal server running at pid: 2188033, started at: 2022-12-21 18:54:33.175496
2022-12-21 18:54:33,181 INFO    WriterThread:2188033 [datastore.py:open_for_write():75] open: /fsx/ganayu/code/SuperShaper/wandb/offline-run-20221221_185428-1tdz4xiy/run-1tdz4xiy.wandb
2022-12-21 18:54:33,181 DEBUG   HandlerThread:2188033 [handler.py:handle_request():141] handle_request: run_start
2022-12-21 18:54:33,193 DEBUG   HandlerThread:2188033 [meta.py:__init__():35] meta init
2022-12-21 18:54:33,193 DEBUG   HandlerThread:2188033 [meta.py:__init__():49] meta init done
2022-12-21 18:54:33,193 DEBUG   HandlerThread:2188033 [meta.py:probe():209] probe
2022-12-21 18:54:33,202 DEBUG   HandlerThread:2188033 [meta.py:_setup_git():199] setup git
2022-12-21 18:54:33,288 DEBUG   HandlerThread:2188033 [meta.py:_setup_git():206] setup git done
2022-12-21 18:54:33,288 DEBUG   HandlerThread:2188033 [meta.py:_save_pip():53] save pip
2022-12-21 18:54:33,292 DEBUG   HandlerThread:2188033 [meta.py:_save_pip():67] save pip done
2022-12-21 18:54:33,293 DEBUG   HandlerThread:2188033 [meta.py:_save_conda():74] save conda
2022-12-21 18:54:42,184 WARNING MainThread:2188033 [internal.py:is_dead():387] Internal process exiting, parent pid 2186824 disappeared
2022-12-21 18:54:42,184 ERROR   MainThread:2188033 [internal.py:wandb_internal():149] Internal process shutdown.
2022-12-21 18:54:42,184 INFO    WriterThread:2188033 [datastore.py:close():279] close: /fsx/ganayu/code/SuperShaper/wandb/offline-run-20221221_185428-1tdz4xiy/run-1tdz4xiy.wandb
2022-12-21 18:54:42,191 INFO    SenderThread:2188033 [sender.py:finish():1111] shutting down sender
2022-12-21 18:54:46,120 DEBUG   HandlerThread:2188033 [meta.py:_save_conda():84] save conda done
2022-12-21 18:54:46,120 DEBUG   HandlerThread:2188033 [meta.py:probe():247] probe done
2022-12-21 18:54:46,802 INFO    HandlerThread:2188033 [handler.py:finish():806] shutting down handler
2022-12-21 18:54:46,803 INFO    MainThread:2188033 [internal.py:handle_exit():80] Internal process exited
